Workbook

Sheet Dashboard
A1: DASHBOARD DO PROJETO
A2: Indicadores consolidados — atualiza automaticamente conforme as demais abas são preenchidas
A4: Orçamento Total (BAC) | B4: =EVM!C4 -> 52800 | D4: SPI Atual (Rodada 1) | E4: =IFERROR(EVM!M7,"-") -> 1
A5: % Concluído (EAP) | B5: =IFERROR(AVERAGE(Cronograma_Orcamento!I13:I56),0) -> 0.022727273 | D5: CPI Atual (Rodada 1) | E5: =IFERROR(EVM!J7,"-") -> 1
A6: Duração Total (dias) | B6: =SUM(Cronograma_Orcamento!D13:D56) -> 44 | D6: Riscos Altos/Muito Altos (≥0,6) | E6: =COUNTIF(Riscos!G5:G18,">=0.6") -> 0

Sheet Capa
B2: PLANO DE PROJETO — CONTROLE INTEGRADO (GPMS)
B3: Base de trabalho para as Rodadas 1, 2 e 3 — não é o entregável final, é a ferramenta de gestão do grupo
B5: Projeto: | C5: Cliente/Tracker de compartilhamento de arquivos (estilo BitTorrent, com tracker central)
B6: Disciplina: | C6: GPMS (TCC00363) — Prof. Rebeca Motta
B7: Grupo (integrantes): | C7: Lucas Ardelino, Carlos Henrique, Felipe, Lucio, Vinicios, Luiz Eduardo
B8: Repositório GitHub: | C8: https://github.com/Iucio/BitTorrentWannaBe (licença MIT)
B10: LEGENDA DE CORES
B11: Texto azul | C11: Campo de entrada — o grupo deve preencher/editar
B12: Texto verde | C12: Valor vinculado (fórmula) de outra aba — não editar diretamente, edite na aba de origem
B13: Texto preto | C13: Fórmula calculada automaticamente — não editar
B14: Fundo azul-claro | C14: Linha de nível 1 da EAP (fase / entrega macro)
B16: GUIA DAS ABAS
B17: Escopo_EAP | C17: Estrutura Analítica do Projeto — escopo do produto e do projeto, decomposto em pacotes de trabalho.
B18: Papeis | C18: Papéis do grupo (GP, PO, Scrum Master, Resp. Configuração, Devs) e integrantes.
B19: Planning_Poker | C19: Estimativa de esforço em consenso para cada pacote de trabalho da EAP.
B20: Cronograma_Orcamento | C20: Datas, duração, custo e Gráfico de Gantt do projeto.
B21: Riscos | C21: Registro de riscos: probabilidade × impacto × exposição, priorização e planos de resposta.
B22: Burndown | C22: Acompanhamento do trabalho restante dentro de uma iteração/sprint.
B23: EVM | C23: Análise de Valor Agregado (PV, EV, AC, SPI, CPI) ao final de cada rodada.
B24: Dashboard | C24: Painel-resumo com os principais indicadores e gráficos do projeto.
B26: Datas das Rodadas (calendário oficial): Rodada 1 = 08–10/09/2026 · Rodada 2 = 06–08/10/2026 · Rodada 3 = 10–12/11/2026.

Sheet Escopo_EAP
A1: ESCOPO DO PROJETO — ESTRUTURA ANALÍTICA (EAP)
A3: ID | B3: Nível | C3: Pacote de Trabalho / Atividade | D3: Descrição | E3: Responsável | F3: Status | G3: Observações
A4: 1 | B4: 1 | C4: Protocolo e Parser | D4: Codificação/decodificação e serialização das mensagens do protocolo tracker/cliente e cliente/cliente | F4: Não iniciado
A5: 1.1 | B5: 2 | C5: Parser B-encode (encode/decode) | D5: Implementação do parser.py — leitura e escrita de int, byte string, lista e dicionário | F5: Concluído
A6: 1.2 | B6: 2 | C6: Testes do parser B-encode | D6: Casos de teste unitários cobrindo encode e decode, incluindo casos de borda | F6: Não iniciado
A7: 1.2.1 | B7: 3 | C7: – Testes de decodificação (inteiros, strings, listas, dicionários) | D7: Casos normais de decode para cada tipo bencode | F7: Não iniciado
A8: 1.2.2 | B8: 3 | C8: – Testes de codificação (dicionário → bencode) | D8: Casos normais de encode a partir de estruturas Python | F8: Não iniciado
A9: 1.2.3 | B9: 3 | C9: – Testes de casos de borda | D9: Bencode aninhado, valores vazios, strings binárias | F9: Não iniciado
A10: 1.3 | B10: 2 | C10: Serialização binária do Peer Wire Protocol (struct) | D10: Empacotamento/desempacotamento das mensagens P2P (length prefix + ID + payload) — ver Anexo A.4 | F10: Não iniciado
A11: 1.3.1 | B11: 3 | C11: – Empacotamento/desempacotamento do Handshake | D11: pstrlen+pstr+reserved+info_hash+peer_id (68 bytes fixos) | F11: Não iniciado
A12: 1.3.2 | B12: 3 | C12: – Empacotamento/desempacotamento de HAVE e BITFIELD | D12: Mensagens de sinalização de posse de peças | F12: Não iniciado
A13: 1.3.3 | B13: 3 | C13: – Empacotamento/desempacotamento de REQUEST e PIECE | D13: Mensagens de transferência de blocos de 16 KiB | F13: Não iniciado
A14: 2 | B14: 1 | C14: Comunicação Cliente–Tracker | D14: Announce request/response e controle de acesso à rede — ver Anexo A.1/A.2 | F14: Não iniciado
A15: 2.1 | B15: 2 | C15: Cadastro/autorização de clientes na rede | D15: Controle de acesso básico — só clientes autorizados recebem resposta do Tracker (domínio fechado) | F15: Não iniciado
A16: 2.1.1 | B16: 3 | C16: – Definir mecanismo de autorização (lista de peer_id permitidos) | F16: Não iniciado
A17: 2.1.2 | B17: 3 | C17: – Implementar verificação de autorização no Tracker | F17: Não iniciado
A18: 2.1.3 | B18: 3 | C18: – Testes de rejeição de cliente não autorizado | F18: Não iniciado
A19: 2.2 | B19: 2 | C19: Implementar Announce Request (cliente → Tracker) | D19: Montagem da requisição HTTP GET com info_hash, peer_id, port, uploaded/downloaded/left, compact, event | F19: Não iniciado
A20: 2.2.1 | B20: 3 | C20: – Montagem da query string (info_hash, peer_id, port, compact) | F20: Não iniciado
A21: 2.2.2 | B21: 3 | C21: – Cálculo de uploaded/downloaded/left | F21: Não iniciado
A22: 2.2.3 | B22: 3 | C22: – Testes do announce request | F22: Não iniciado
A23: 2.3 | B23: 2 | C23: Implementar Announce Response (Tracker → cliente) | D23: Servidor Tracker: mantém tabela info_hash → lista de peers e responde em Bencode (interval, peers, complete, incomplete) | F23: Não iniciado
A24: 2.3.1 | B24: 3 | C24: – Tabela info_hash → lista de peers no Tracker | F24: Não iniciado
A25: 2.3.2 | B25: 3 | C25: – Formato compacto de peers (compact=1) | F25: Não iniciado
A26: 2.3.3 | B26: 3 | C26: – Contadores complete/incomplete | F26: Não iniciado
A27: 2.4 | B27: 2 | C27: Tratamento da resposta pelo cliente | D27: Cliente interpreta a resposta do Tracker e extrai a lista de peers a contatar | F27: Não iniciado
A28: 2.4.1 | B28: 3 | C28: – Parsing da resposta Bencode | F28: Não iniciado
A29: 2.4.2 | B29: 3 | C29: – Extração e tratamento da lista de peers | F29: Não iniciado
A30: 2.4.3 | B30: 3 | C30: – Tratamento de failure reason | F30: Não iniciado
A31: 3 | B31: 1 | C31: Comunicação entre Clientes (Peer Wire Protocol) | D31: Handshake e troca de fragmentos entre peers — ver Anexo A.3/A.4 | F31: Não iniciado
A32: 3.1 | B32: 2 | C32: Handshake entre peers | D32: Troca dos 68 bytes fixos e validação do info_hash | F32: Não iniciado
A33: 3.1.1 | B33: 3 | C33: – Envio do handshake | F33: Não iniciado
A34: 3.1.2 | B34: 3 | C34: – Validação do info_hash recebido | F34: Não iniciado
A35: 3.2 | B35: 2 | C35: Anúncio de posses (BITFIELD) | D35: Seeder envia vetor de bits indicando as peças que possui (ID 5) | F35: Não iniciado
A36: 3.2.1 | B36: 3 | C36: – Geração do bitfield local | F36: Não iniciado
A37: 3.2.2 | B37: 3 | C37: – Leitura do bitfield remoto | F37: Não iniciado
A38: 3.3 | B38: 2 | C38: Controle de fluxo (INTERESTED/UNCHOKE) | D38: Leecher sinaliza interesse (ID 2) e Seeder libera banda (ID 1) | F38: Não iniciado
A39: 3.3.1 | B39: 3 | C39: – Envio de INTERESTED | F39: Não iniciado
A40: 3.3.2 | B40: 3 | C40: – Lógica de UNCHOKE (liberação de banda) | F40: Não iniciado
A41: 3.4 | B41: 2 | C41: Loop de requisição e entrega de blocos (REQUEST/PIECE) | D41: Requisição de blocos de 16 KiB (ID 6) e entrega dos dados binários (ID 7) | F41: Não iniciado
...

Sheet Papeis
A1: PAPÉIS E RESPONSABILIDADES DO GRUPO
A3: Papel | B3: Integrante(s) | C3: Responsabilidades principais | D3: Acumula outro papel? | E3: Justificativa (se acumula)
A4: Gerente de Projeto (GP) | B4: Lucas Ardelino | C4: Consolida o plano de projeto (escopo, cronograma, orçamento, riscos); conduz o monitoramento e controle (EVM/burndown); reporta o andamento nas apresentações. | D4: Não
A5: Product Owner (PO) | B5: Felipe | C5: Define e prioriza requisitos/backlog; representa a visão do produto; decide o que entra em cada iteração. | D5: Sim | E5: Acumula com Desenvolvedor(a) para reforçar a frente de implementação.
A6: Scrum Master / Facilitador | B6: Carlos Henrique | C6: Conduz as cerimônias (planning, daily, review, retrospectiva); remove impedimentos; garante que o processo está sendo seguido. | D6: Sim | E6: Acumula com Desenvolvedor(a) para reforçar a frente de implementação.
A7: Responsável por Configuração | B7: Lucio | C7: Define e mantém a estratégia de branches, organiza issues/milestones no GitHub, garante que o repositório está íntegro e documentado. | D7: Não
A8: Desenvolvedor(a) 1 | B8: Felipe | C8: Implementa o produto; participa das estimativas (Planning Poker); registra horas previstas e realizadas de cada tarefa. | D8: Sim | E8: Acumula com Product Owner.
A9: Desenvolvedor(a) 2 | B9: Carlos Henrique | C9: Implementa o produto; participa das estimativas (Planning Poker); registra horas previstas e realizadas de cada tarefa. | D9: Sim | E9: Acumula com Scrum Master.
A10: Desenvolvedor(a) 3 | B10: Vinicios | C10: Implementa o produto; participa das estimativas (Planning Poker); registra horas previstas e realizadas de cada tarefa. | D10: Não
A11: Desenvolvedor(a) 4 | B11: Luiz Eduardo | C11: Implementa o produto; participa das estimativas (Planning Poker); registra horas previstas e realizadas de cada tarefa. | D11: Não
A14: INTEGRANTES DO GRUPO
A15: Nome | B15: Papel Principal | C15: Papel(éis) Adicional(is)
A16: Lucas Ardelino | B16: Gerente de Projeto (GP)
A17: Carlos Henrique | B17: Scrum Master / Facilitador | C17: Desenvolvedor(a)
A18: Felipe | B18: Product Owner (PO) | C18: Desenvolvedor(a)
A19: Lucio | B19: Responsável por Configuração
A20: Vinicios | B20: Desenvolvedor(a)
A21: Luiz Eduardo | B21: Desenvolvedor(a)

Sheet Planning_Poker
A1: PLANNING POKER — ESTIMATIVA DE ESFORÇO
A2: Estimativa de consenso sobre cada pacote de trabalho da EAP (inclui modelagem, testes e integração — não só código)
A3: ID (EAP) | B3: Pacote de Trabalho | C3: Lucas Ardelino | D3: Carlos Henrique | E3: Felipe | F3: Lucio | G3: Vinicios | H3: Luiz Eduardo | I3: Média | J3: Estimativa Final (consenso) | K3: Unidade | L3: Observações
A4: =Escopo_EAP!A5 -> 1.1 | B4: =TRIM(Escopo_EAP!C5) -> Parser B-encode (encode/decode) | C4: 1 | D4: 0.5 | E4: 1 | F4: 0.5 | G4: 1 | H4: 1 | I4: =IFERROR(AVERAGE(C4:H4),"") -> 0.83333333 | J4: 1 | K4: Homem-dia
A5: =Escopo_EAP!A7 -> 1.2.1 | B5: =TRIM(Escopo_EAP!C7) -> – Testes de decodificação (inteiros, strings, listas, dicionários) | C5: 0.5 | D5: 0.5 | E5: 0.5 | F5: 0.5 | G5: 0.5 | H5: 0.5 | I5: =IFERROR(AVERAGE(C5:H5),"") -> 0.5 | J5: 0.5 | K5: Homem-dia
A6: =Escopo_EAP!A8 -> 1.2.2 | B6: =TRIM(Escopo_EAP!C8) -> – Testes de codificação (dicionário → bencode) | C6: 0.5 | D6: 0.5 | E6: 0.5 | F6: 0.5 | G6: 0.5 | H6: 0.5 | I6: =IFERROR(AVERAGE(C6:H6),"") -> 0.5 | J6: 0.5 | K6: Homem-dia
A7: =Escopo_EAP!A9 -> 1.2.3 | B7: =TRIM(Escopo_EAP!C9) -> – Testes de casos de borda | C7: 0.5 | D7: 0.5 | E7: 0.5 | F7: 0.5 | G7: 0.5 | H7: 0.5 | I7: =IFERROR(AVERAGE(C7:H7),"") -> 0.5 | J7: 0.5 | K7: Homem-dia
A8: =Escopo_EAP!A11 -> 1.3.1 | B8: =TRIM(Escopo_EAP!C11) -> – Empacotamento/desempacotamento do Handshake | C8: 0.5 | D8: 0.5 | E8: 1 | F8: 1.5 | G8: 0.5 | H8: 1 | I8: =IFERROR(AVERAGE(C8:H8),"") -> 0.83333333 | J8: 1 | K8: Homem-dia
A9: =Escopo_EAP!A12 -> 1.3.2 | B9: =TRIM(Escopo_EAP!C12) -> – Empacotamento/desempacotamento de HAVE e BITFIELD | C9: 1 | D9: 1 | E9: 1 | F9: 0.5 | G9: 0.5 | H9: 1 | I9: =IFERROR(AVERAGE(C9:H9),"") -> 0.83333333 | J9: 1 | K9: Homem-dia
A10: =Escopo_EAP!A13 -> 1.3.3 | B10: =TRIM(Escopo_EAP!C13) -> – Empacotamento/desempacotamento de REQUEST e PIECE | C10: 1 | D10: 1 | E10: 1 | F10: 1 | G10: 1 | H10: 1 | I10: =IFERROR(AVERAGE(C10:H10),"") -> 1 | J10: 1 | K10: Homem-dia
A11: =Escopo_EAP!A16 -> 2.1.1 | B11: =TRIM(Escopo_EAP!C16) -> – Definir mecanismo de autorização (lista de peer_id permitidos) | C11: 0.5 | D11: 0.5 | E11: 0.5 | F11: 0.5 | G11: 0.5 | H11: 0.5 | I11: =IFERROR(AVERAGE(C11:H11),"") -> 0.5 | J11: 0.5 | K11: Homem-dia
A12: =Escopo_EAP!A17 -> 2.1.2 | B12: =TRIM(Escopo_EAP!C17) -> – Implementar verificação de autorização no Tracker | C12: 1 | D12: 1 | E12: 1.5 | F12: 0.5 | G12: 1 | H12: 1 | I12: =IFERROR(AVERAGE(C12:H12),"") -> 1 | J12: 1 | K12: Homem-dia
A13: =Escopo_EAP!A18 -> 2.1.3 | B13: =TRIM(Escopo_EAP!C18) -> – Testes de rejeição de cliente não autorizado | C13: 0.5 | D13: 0.5 | E13: 0.5 | F13: 0.5 | G13: 0.5 | H13: 0.5 | I13: =IFERROR(AVERAGE(C13:H13),"") -> 0.5 | J13: 0.5 | K13: Homem-dia
A14: =Escopo_EAP!A20 -> 2.2.1 | B14: =TRIM(Escopo_EAP!C20) -> – Montagem da query string (info_hash, peer_id, port, compact) | C14: 1.5 | D14: 1 | E14: 1 | F14: 1 | G14: 1 | H14: 1 | I14: =IFERROR(AVERAGE(C14:H14),"") -> 1.0833333 | J14: 1 | K14: Homem-dia
A15: =Escopo_EAP!A21 -> 2.2.2 | B15: =TRIM(Escopo_EAP!C21) -> – Cálculo de uploaded/downloaded/left | C15: 0.5 | D15: 0.5 | E15: 0.5 | F15: 0.5 | G15: 0.5 | H15: 0.5 | I15: =IFERROR(AVERAGE(C15:H15),"") -> 0.5 | J15: 0.5 | K15: Homem-dia
A16: =Escopo_EAP!A22 -> 2.2.3 | B16: =TRIM(Escopo_EAP!C22) -> – Testes do announce request | C16: 0.5 | D16: 0.5 | E16: 0.5 | F16: 0.5 | G16: 0.5 | H16: 0.5 | I16: =IFERROR(AVERAGE(C16:H16),"") -> 0.5 | J16: 0.5 | K16: Homem-dia
A17: =Escopo_EAP!A24 -> 2.3.1 | B17: =TRIM(Escopo_EAP!C24) -> – Tabela info_hash → lista de peers no Tracker | C17: 0.5 | D17: 1 | E17: 0.5 | F17: 0.5 | G17: 0.5 | H17: 1 | I17: =IFERROR(AVERAGE(C17:H17),"") -> 0.66666667 | J17: 1 | K17: Homem-dia
A18: =Escopo_EAP!A25 -> 2.3.2 | B18: =TRIM(Escopo_EAP!C25) -> – Formato compacto de peers (compact=1) | C18: 0.5 | D18: 1 | E18: 1 | F18: 1.5 | G18: 0.5 | H18: 1 | I18: =IFERROR(AVERAGE(C18:H18),"") -> 0.91666667 | J18: 1 | K18: Homem-dia
A19: =Escopo_EAP!A26 -> 2.3.3 | B19: =TRIM(Escopo_EAP!C26) -> – Contadores complete/incomplete | C19: 0.5 | D19: 0.5 | E19: 0.5 | F19: 0.5 | G19: 0.5 | H19: 0.5 | I19: =IFERROR(AVERAGE(C19:H19),"") -> 0.5 | J19: 0.5 | K19: Homem-dia
A20: =Escopo_EAP!A28 -> 2.4.1 | B20: =TRIM(Escopo_EAP!C28) -> – Parsing da resposta Bencode | C20: 0.5 | D20: 0.5 | E20: 0.5 | F20: 0.5 | G20: 0.5 | H20: 0.5 | I20: =IFERROR(AVERAGE(C20:H20),"") -> 0.5 | J20: 0.5 | K20: Homem-dia
A21: =Escopo_EAP!A29 -> 2.4.2 | B21: =TRIM(Escopo_EAP!C29) -> – Extração e tratamento da lista de peers | C21: 0.5 | D21: 0.5 | E21: 0.5 | F21: 0.5 | G21: 0.5 | H21: 0.5 | I21: =IFERROR(AVERAGE(C21:H21),"") -> 0.5 | J21: 0.5 | K21: Homem-dia
A22: =Escopo_EAP!A30 -> 2.4.3 | B22: =TRIM(Escopo_EAP!C30) -> – Tratamento de failure reason | C22: 0.5 | D22: 0.5 | E22: 0.5 | F22: 0.5 | G22: 0.5 | H22: 0.5 | I22: =IFERROR(AVERAGE(C22:H22),"") -> 0.5 | J22: 0.5 | K22: Homem-dia
A23: =Escopo_EAP!A33 -> 3.1.1 | B23: =TRIM(Escopo_EAP!C33) -> – Envio do handshake | C23: 1 | D23: 0.5 | E23: 1.5 | F23: 1 | G23: 1.5 | H23: 1 | I23: =IFERROR(AVERAGE(C23:H23),"") -> 1.0833333 | J23: 1 | K23: Homem-dia
A24: =Escopo_EAP!A34 -> 3.1.2 | B24: =TRIM(Escopo_EAP!C34) -> – Validação do info_hash recebido | C24: 0.5 | D24: 0.5 | E24: 0.5 | F24: 0.5 | G24: 0.5 | H24: 0.5 | I24: =IFERROR(AVERAGE(C24:H24),"") -> 0.5 | J24: 0.5 | K24: Homem-dia
A25: =Escopo_EAP!A36 -> 3.2.1 | B25: =TRIM(Escopo_EAP!C36) -> – Geração do bitfield local | C25: 1 | D25: 0.5 | E25: 1 | F25: 0.5 | G25: 0.5 | H25: 0.5 | I25: =IFERROR(AVERAGE(C25:H25),"") -> 0.66666667 | J25: 1 | K25: Homem-dia
A26: =Escopo_EAP!A37 -> 3.2.2 | B26: =TRIM(Escopo_EAP!C37) -> – Leitura do bitfield remoto | C26: 0.5 | D26: 0.5 | E26: 0.5 | F26: 0.5 | G26: 0.5 | H26: 0.5 | I26: =IFERROR(AVERAGE(C26:H26),"") -> 0.5 | J26: 0.5 | K26: Homem-dia
A27: =Escopo_EAP!A39 -> 3.3.1 | B27: =TRIM(Escopo_EAP!C39) -> – Envio de INTERESTED | C27: 0.5 | D27: 0.5 | E27: 0.5 | F27: 0.5 | G27: 0.5 | H27: 0.5 | I27: =IFERROR(AVERAGE(C27:H27),"") -> 0.5 | J27: 0.5 | K27: Homem-dia
A28: =Escopo_EAP!A40 -> 3.3.2 | B28: =TRIM(Escopo_EAP!C40) -> – Lógica de UNCHOKE (liberação de banda) | C28: 1 | D28: 1 | E28: 0.5 | F28: 0.5 | G28: 1 | H28: 1 | I28: =IFERROR(AVERAGE(C28:H28),"") -> 0.83333333 | J28: 1 | K28: Homem-dia
A29: =Escopo_EAP!A42 -> 3.4.1 | B29: =TRIM(Escopo_EAP!C42) -> – Envio de REQUEST por bloco (16 KiB) | C29: 1.5 | D29: 0.5 | E29: 0.5 | F29: 1.5 | G29: 1 | H29: 0.5 | I29: =IFERROR(AVERAGE(C29:H29),"") -> 0.91666667 | J29: 1 | K29: Homem-dia
A30: =Escopo_EAP!A43 -> 3.4.2 | B30: =TRIM(Escopo_EAP!C43) -> – Recebimento e buffer de PIECE | C30: 1 | D30: 0.5 | E30: 1 | F30: 1.5 | G30: 1.5 | H30: 1 | I30: =IFERROR(AVERAGE(C30:H30),"") -> 1.0833333 | J30: 1 | K30: Homem-dia
A31: =Escopo_EAP!A44 -> 3.4.3 | B31: =TRIM(Escopo_EAP!C44) -> – Controle do loop até completar a peça | C31: 1 | D31: 1 | E31: 0.5 | F31: 1 | G31: 1 | H31: 1 | I31: =IFERROR(AVERAGE(C31:H31),"") -> 0.91666667 | J31: 1 | K31: Homem-dia
A32: =Escopo_EAP!A46 -> 3.5.1 | B32: =TRIM(Escopo_EAP!C46) -> – Validação de peça completa (hash) | C32: 1 | D32: 1 | E32: 1 | F32: 1.5 | G32: 1.5 | H32: 1 | I32: =IFERROR(AVERAGE(C32:H32),"") -> 1.1666667 | J32: 1 | K32: Homem-dia
A33: =Escopo_EAP!A47 -> 3.5.2 | B33: =TRIM(Escopo_EAP!C47) -> – Broadcast de HAVE aos peers | C33: 0.5 | D33: 0.5 | E33: 0.5 | F33: 0.5 | G33: 0.5 | H33: 0.5 | I33: =IFERROR(AVERAGE(C33:H33),"") -> 0.5 | J33: 0.5 | K33: Homem-dia
A34: =Escopo_EAP!A50 -> 4.1.1 | B34: =TRIM(Escopo_EAP!C50) -> – Abertura e manutenção da conexão TCP | C34: 1 | D34: 1 | E34: 1 | F34: 1.5 | G34: 2 | H34: 1.5 | I34: =IFERROR(AVERAGE(C34:H34),"") -> 1.3333333 | J34: 1.5 | K34: Homem-dia
A35: =Escopo_EAP!A51 -> 4.1.2 | B35: =TRIM(Escopo_EAP!C51) -> – Tratamento de timeout/reconexão | C35: 1.5 | D35: 1.5 | E35: 1.5 | F35: 1 | G35: 1 | H35: 1 | I35: =IFERROR(AVERAGE(C35:H35),"") -> 1.25 | J35: 1 | K35: Homem-dia
A36: =Escopo_EAP!A53 -> 4.2.1 | B36: =TRIM(Escopo_EAP!C53) -> – Buffer de peça em memória | C36: 1 | D36: 1 | E36: 1 | F36: 1.5 | G36: 1.5 | H36: 1 | I36: =IFERROR(AVERAGE(C36:H36),"") -> 1.1666667 | J36: 1 | K36: Homem-dia
A37: =Escopo_EAP!A54 -> 4.2.2 | B37: =TRIM(Escopo_EAP!C54) -> – Escrita da peça validada no arquivo final | C37: 1 | D37: 1 | E37: 0.5 | F37: 1 | G37: 1.5 | H37: 1 | I37: =IFERROR(AVERAGE(C37:H37),"") -> 1 | J37: 1 | K37: Homem-dia
A38: =Escopo_EAP!A56 -> 4.3.1 | B38: =TRIM(Escopo_EAP!C56) -> – Cálculo de hash SHA-1 por peça | C38: 0.5 | D38: 0.5 | E38: 0.5 | F38: 0.5 | G38: 0.5 | H38: 0.5 | I38: =IFERROR(AVERAGE(C38:H38),"") -> 0.5 | J38: 0.5 | K38: Homem-dia
A39: =Escopo_EAP!A57 -> 4.3.2 | B39: =TRIM(Escopo_EAP!C57) -> – Comparação com hash esperado e tratamento de falha | C39: 0.5 | D39: 0.5 | E39: 0.5 | F39: 0.5 | G39: 0.5 | H39: 0.5 | I39: =IFERROR(AVERAGE(C39:H39),"") -> 0.5 | J39: 0.5 | K39: Homem-dia
A40: =Escopo_EAP!A59 -> 5.1 | B40: =TRIM(Escopo_EAP!C59) -> Upload de arquivos (fragmentação e catalogação) | C40: 2 | D40: 2 | E40: 4 | F40: 3.5 | G40: 2 | H40: 4 | I40: =IFERROR(AVERAGE(C40:H40),"") -> 2.9166667 | J40: 3 | K40: Homem-dia
...

Sheet Cronograma_Orcamento
A1: ORÇAMENTO E CRONOGRAMA (GANTT)
A2: A Rodada 1 é só planejamento — a execução dos sprints começa depois dela, não antes
A4: Prova de conceito (parser) — concluída em: | C4: 46260 | E4: Demonstrado como v1 na Rodada 1 (08/09/2026)
A5: Sprint 1 (Fases 1-4, núcleo) — início: | C5: 46274 | E5: Meta: Rodada 2 — 06/10/2026
A6: Sprint 2 (Fase 5-6) — início: | C6: 46302 | E6: Meta: Rodada 3 — 10/11/2026
A7: Custo por hora do desenvolvedor (R$): | C7: 150
A8: Jornada (horas/dia útil): | C8: 8
A9: Custo por homem-dia (R$): | C9: =C7*C8 -> 1200
A10: A Rodada 1 entrega o PLANEJAMENTO (este documento) — só o parser (1.1) precisa estar pronto antes dela. A execução dos sprints roda depois de cada rodada, até a meta da rodada seguinte, para não parecer atraso o que na verdade ainda não começou.
A12: ID | B12: Atividade | C12: Responsável | D12: Duração (dias) | E12: Data Início | F12: Data Fim | G12: Predecessora | H12: Custo Total (R$) | I12: % Concluído | J12: Status | K12: Dias até início | L12: Sprint / Meta
A13: =Escopo_EAP!A5 -> 1.1 | B13: =TRIM(Escopo_EAP!C5) -> Parser B-encode (encode/decode) | C13: Felipe | D13: =IFERROR(Planning_Poker!J4,0) -> 1 | E13: =$C$4 -> 46260 | F13: =E13+D13 -> 46261 | H13: =D13*$C$9 -> 1200 | I13: 1 | J13: Concluído | K13: =E13-$C$4 -> 0 | L13: Pré-Rodada 1 (concluído)
A14: =Escopo_EAP!A7 -> 1.2.1 | B14: =TRIM(Escopo_EAP!C7) -> – Testes de decodificação (inteiros, strings, listas, dicionários) | C14: Carlos Henrique | D14: =IFERROR(Planning_Poker!J5,0) -> 0.5 | E14: =$C$5 -> 46274 | F14: =E14+D14 -> 46274.5 | G14: 1.1 | H14: =D14*$C$9 -> 600 | I14: 0 | J14: Não iniciado | K14: =E14-$C$4 -> 14 | L14: Sprint 1 (Rodada 1 -> Rodada 2)
A15: =Escopo_EAP!A8 -> 1.2.2 | B15: =TRIM(Escopo_EAP!C8) -> – Testes de codificação (dicionário → bencode) | C15: Carlos Henrique | D15: =IFERROR(Planning_Poker!J6,0) -> 0.5 | E15: =F14 -> 46274.5 | F15: =E15+D15 -> 46275 | G15: 1.2.1 | H15: =D15*$C$9 -> 600 | I15: 0 | J15: Não iniciado | K15: =E15-$C$4 -> 14.5 | L15: Sprint 1 (Rodada 1 -> Rodada 2)
A16: =Escopo_EAP!A9 -> 1.2.3 | B16: =TRIM(Escopo_EAP!C9) -> – Testes de casos de borda | C16: Carlos Henrique | D16: =IFERROR(Planning_Poker!J7,0) -> 0.5 | E16: =F15 -> 46275 | F16: =E16+D16 -> 46275.5 | G16: 1.2.2 | H16: =D16*$C$9 -> 600 | I16: 0 | J16: Não iniciado | K16: =E16-$C$4 -> 15 | L16: Sprint 1 (Rodada 1 -> Rodada 2)
A17: =Escopo_EAP!A11 -> 1.3.1 | B17: =TRIM(Escopo_EAP!C11) -> – Empacotamento/desempacotamento do Handshake | C17: Carlos Henrique | D17: =IFERROR(Planning_Poker!J8,0) -> 1 | E17: =F16 -> 46275.5 | F17: =E17+D17 -> 46276.5 | H17: =D17*$C$9 -> 1200 | I17: 0 | J17: Não iniciado | K17: =E17-$C$4 -> 15.5 | L17: Sprint 1 (Rodada 1 -> Rodada 2)
A18: =Escopo_EAP!A12 -> 1.3.2 | B18: =TRIM(Escopo_EAP!C12) -> – Empacotamento/desempacotamento de HAVE e BITFIELD | C18: Carlos Henrique | D18: =IFERROR(Planning_Poker!J9,0) -> 1 | E18: =F17 -> 46276.5 | F18: =E18+D18 -> 46277.5 | G18: 1.3.1 | H18: =D18*$C$9 -> 1200 | I18: 0 | J18: Não iniciado | K18: =E18-$C$4 -> 16.5 | L18: Sprint 1 (Rodada 1 -> Rodada 2)
A19: =Escopo_EAP!A13 -> 1.3.3 | B19: =TRIM(Escopo_EAP!C13) -> – Empacotamento/desempacotamento de REQUEST e PIECE | C19: Carlos Henrique | D19: =IFERROR(Planning_Poker!J10,0) -> 1 | E19: =F18 -> 46277.5 | F19: =E19+D19 -> 46278.5 | G19: 1.3.2 | H19: =D19*$C$9 -> 1200 | I19: 0 | J19: Não iniciado | K19: =E19-$C$4 -> 17.5 | L19: Sprint 1 (Rodada 1 -> Rodada 2)
A20: =Escopo_EAP!A16 -> 2.1.1 | B20: =TRIM(Escopo_EAP!C16) -> – Definir mecanismo de autorização (lista de peer_id permitidos) | C20: Felipe | D20: =IFERROR(Planning_Poker!J11,0) -> 0.5 | E20: =F19 -> 46278.5 | F20: =E20+D20 -> 46279 | G20: 1.1 | H20: =D20*$C$9 -> 600 | I20: 0 | J20: Não iniciado | K20: =E20-$C$4 -> 18.5 | L20: Sprint 1 (Rodada 1 -> Rodada 2)
A21: =Escopo_EAP!A17 -> 2.1.2 | B21: =TRIM(Escopo_EAP!C17) -> – Implementar verificação de autorização no Tracker | C21: Felipe | D21: =IFERROR(Planning_Poker!J12,0) -> 1 | E21: =F20 -> 46279 | F21: =E21+D21 -> 46280 | G21: 2.1.1 | H21: =D21*$C$9 -> 1200 | I21: 0 | J21: Não iniciado | K21: =E21-$C$4 -> 19 | L21: Sprint 1 (Rodada 1 -> Rodada 2)
A22: =Escopo_EAP!A18 -> 2.1.3 | B22: =TRIM(Escopo_EAP!C18) -> – Testes de rejeição de cliente não autorizado | C22: Felipe | D22: =IFERROR(Planning_Poker!J13,0) -> 0.5 | E22: =F21 -> 46280 | F22: =E22+D22 -> 46280.5 | G22: 2.1.2 | H22: =D22*$C$9 -> 600 | I22: 0 | J22: Não iniciado | K22: =E22-$C$4 -> 20 | L22: Sprint 1 (Rodada 1 -> Rodada 2)
A23: =Escopo_EAP!A20 -> 2.2.1 | B23: =TRIM(Escopo_EAP!C20) -> – Montagem da query string (info_hash, peer_id, port, compact) | C23: Felipe | D23: =IFERROR(Planning_Poker!J14,0) -> 1 | E23: =F22 -> 46280.5 | F23: =E23+D23 -> 46281.5 | G23: 2.1.3 | H23: =D23*$C$9 -> 1200 | I23: 0 | J23: Não iniciado | K23: =E23-$C$4 -> 20.5 | L23: Sprint 1 (Rodada 1 -> Rodada 2)
A24: =Escopo_EAP!A21 -> 2.2.2 | B24: =TRIM(Escopo_EAP!C21) -> – Cálculo de uploaded/downloaded/left | C24: Felipe | D24: =IFERROR(Planning_Poker!J15,0) -> 0.5 | E24: =F23 -> 46281.5 | F24: =E24+D24 -> 46282 | G24: 2.2.1 | H24: =D24*$C$9 -> 600 | I24: 0 | J24: Não iniciado | K24: =E24-$C$4 -> 21.5 | L24: Sprint 1 (Rodada 1 -> Rodada 2)
A25: =Escopo_EAP!A22 -> 2.2.3 | B25: =TRIM(Escopo_EAP!C22) -> – Testes do announce request | C25: Felipe | D25: =IFERROR(Planning_Poker!J16,0) -> 0.5 | E25: =F24 -> 46282 | F25: =E25+D25 -> 46282.5 | G25: 2.2.2 | H25: =D25*$C$9 -> 600 | I25: 0 | J25: Não iniciado | K25: =E25-$C$4 -> 22 | L25: Sprint 1 (Rodada 1 -> Rodada 2)
A26: =Escopo_EAP!A24 -> 2.3.1 | B26: =TRIM(Escopo_EAP!C24) -> – Tabela info_hash → lista de peers no Tracker | C26: Felipe | D26: =IFERROR(Planning_Poker!J17,0) -> 1 | E26: =F25 -> 46282.5 | F26: =E26+D26 -> 46283.5 | G26: 2.1.3 | H26: =D26*$C$9 -> 1200 | I26: 0 | J26: Não iniciado | K26: =E26-$C$4 -> 22.5 | L26: Sprint 1 (Rodada 1 -> Rodada 2)
A27: =Escopo_EAP!A25 -> 2.3.2 | B27: =TRIM(Escopo_EAP!C25) -> – Formato compacto de peers (compact=1) | C27: Felipe | D27: =IFERROR(Planning_Poker!J18,0) -> 1 | E27: =F26 -> 46283.5 | F27: =E27+D27 -> 46284.5 | G27: 2.3.1 | H27: =D27*$C$9 -> 1200 | I27: 0 | J27: Não iniciado | K27: =E27-$C$4 -> 23.5 | L27: Sprint 1 (Rodada 1 -> Rodada 2)
A28: =Escopo_EAP!A26 -> 2.3.3 | B28: =TRIM(Escopo_EAP!C26) -> – Contadores complete/incomplete | C28: Felipe | D28: =IFERROR(Planning_Poker!J19,0) -> 0.5 | E28: =F27 -> 46284.5 | F28: =E28+D28 -> 46285 | G28: 2.3.2 | H28: =D28*$C$9 -> 600 | I28: 0 | J28: Não iniciado | K28: =E28-$C$4 -> 24.5 | L28: Sprint 1 (Rodada 1 -> Rodada 2)
A29: =Escopo_EAP!A28 -> 2.4.1 | B29: =TRIM(Escopo_EAP!C28) -> – Parsing da resposta Bencode | C29: Felipe | D29: =IFERROR(Planning_Poker!J20,0) -> 0.5 | E29: =F28 -> 46285 | F29: =E29+D29 -> 46285.5 | G29: 2.2.3;2.3.3 | H29: =D29*$C$9 -> 600 | I29: 0 | J29: Não iniciado | K29: =E29-$C$4 -> 25 | L29: Sprint 1 (Rodada 1 -> Rodada 2)
A30: =Escopo_EAP!A29 -> 2.4.2 | B30: =TRIM(Escopo_EAP!C29) -> – Extração e tratamento da lista de peers | C30: Felipe | D30: =IFERROR(Planning_Poker!J21,0) -> 0.5 | E30: =F29 -> 46285.5 | F30: =E30+D30 -> 46286 | G30: 2.4.1 | H30: =D30*$C$9 -> 600 | I30: 0 | J30: Não iniciado | K30: =E30-$C$4 -> 25.5 | L30: Sprint 1 (Rodada 1 -> Rodada 2)
A31: =Escopo_EAP!A30 -> 2.4.3 | B31: =TRIM(Escopo_EAP!C30) -> – Tratamento de failure reason | C31: Felipe | D31: =IFERROR(Planning_Poker!J22,0) -> 0.5 | E31: =F30 -> 46286 | F31: =E31+D31 -> 46286.5 | G31: 2.4.2 | H31: =D31*$C$9 -> 600 | I31: 0 | J31: Não iniciado | K31: =E31-$C$4 -> 26 | L31: Sprint 1 (Rodada 1 -> Rodada 2)
A32: =Escopo_EAP!A33 -> 3.1.1 | B32: =TRIM(Escopo_EAP!C33) -> – Envio do handshake | C32: Vinicios | D32: =IFERROR(Planning_Poker!J23,0) -> 1 | E32: =F31 -> 46286.5 | F32: =E32+D32 -> 46287.5 | G32: 2.4.3 | H32: =D32*$C$9 -> 1200 | I32: 0 | J32: Não iniciado | K32: =E32-$C$4 -> 26.5 | L32: Sprint 1 (Rodada 1 -> Rodada 2)
A33: =Escopo_EAP!A34 -> 3.1.2 | B33: =TRIM(Escopo_EAP!C34) -> – Validação do info_hash recebido | C33: Vinicios | D33: =IFERROR(Planning_Poker!J24,0) -> 0.5 | E33: =F32 -> 46287.5 | F33: =E33+D33 -> 46288 | G33: 3.1.1 | H33: =D33*$C$9 -> 600 | I33: 0 | J33: Não iniciado | K33: =E33-$C$4 -> 27.5 | L33: Sprint 1 (Rodada 1 -> Rodada 2)
A34: =Escopo_EAP!A36 -> 3.2.1 | B34: =TRIM(Escopo_EAP!C36) -> – Geração do bitfield local | C34: Vinicios | D34: =IFERROR(Planning_Poker!J25,0) -> 1 | E34: =F33 -> 46288 | F34: =E34+D34 -> 46289 | G34: 3.1.2 | H34: =D34*$C$9 -> 1200 | I34: 0 | J34: Não iniciado | K34: =E34-$C$4 -> 28 | L34: Sprint 1 (Rodada 1 -> Rodada 2)
A35: =Escopo_EAP!A37 -> 3.2.2 | B35: =TRIM(Escopo_EAP!C37) -> – Leitura do bitfield remoto | C35: Vinicios | D35: =IFERROR(Planning_Poker!J26,0) -> 0.5 | E35: =F34 -> 46289 | F35: =E35+D35 -> 46289.5 | G35: 3.2.1 | H35: =D35*$C$9 -> 600 | I35: 0 | J35: Não iniciado | K35: =E35-$C$4 -> 29 | L35: Sprint 1 (Rodada 1 -> Rodada 2)
A36: =Escopo_EAP!A39 -> 3.3.1 | B36: =TRIM(Escopo_EAP!C39) -> – Envio de INTERESTED | C36: Vinicios | D36: =IFERROR(Planning_Poker!J27,0) -> 0.5 | E36: =F35 -> 46289.5 | F36: =E36+D36 -> 46290 | G36: 3.2.2 | H36: =D36*$C$9 -> 600 | I36: 0 | J36: Não iniciado | K36: =E36-$C$4 -> 29.5 | L36: Sprint 1 (Rodada 1 -> Rodada 2)
A37: =Escopo_EAP!A40 -> 3.3.2 | B37: =TRIM(Escopo_EAP!C40) -> – Lógica de UNCHOKE (liberação de banda) | C37: Vinicios | D37: =IFERROR(Planning_Poker!J28,0) -> 1 | E37: =F36 -> 46290 | F37: =E37+D37 -> 46291 | G37: 3.3.1 | H37: =D37*$C$9 -> 1200 | I37: 0 | J37: Não iniciado | K37: =E37-$C$4 -> 30 | L37: Sprint 1 (Rodada 1 -> Rodada 2)
A38: =Escopo_EAP!A42 -> 3.4.1 | B38: =TRIM(Escopo_EAP!C42) -> – Envio de REQUEST por bloco (16 KiB) | C38: Vinicios | D38: =IFERROR(Planning_Poker!J29,0) -> 1 | E38: =F37 -> 46291 | F38: =E38+D38 -> 46292 | G38: 3.3.2 | H38: =D38*$C$9 -> 1200 | I38: 0 | J38: Não iniciado | K38: =E38-$C$4 -> 31 | L38: Sprint 1 (Rodada 1 -> Rodada 2)
A39: =Escopo_EAP!A43 -> 3.4.2 | B39: =TRIM(Escopo_EAP!C43) -> – Recebimento e buffer de PIECE | C39: Vinicios | D39: =IFERROR(Planning_Poker!J30,0) -> 1 | E39: =F38 -> 46292 | F39: =E39+D39 -> 46293 | G39: 3.4.1 | H39: =D39*$C$9 -> 1200 | I39: 0 | J39: Não iniciado | K39: =E39-$C$4 -> 32 | L39: Sprint 1 (Rodada 1 -> Rodada 2)
A40: =Escopo_EAP!A44 -> 3.4.3 | B40: =TRIM(Escopo_EAP!C44) -> – Controle do loop até completar a peça | C40: Vinicios | D40: =IFERROR(Planning_Poker!J31,0) -> 1 | E40: =F39 -> 46293 | F40: =E40+D40 -> 46294 | G40: 3.4.2 | H40: =D40*$C$9 -> 1200 | I40: 0 | J40: Não iniciado | K40: =E40-$C$4 -> 33 | L40: Sprint 1 (Rodada 1 -> Rodada 2)
A41: =Escopo_EAP!A46 -> 3.5.1 | B41: =TRIM(Escopo_EAP!C46) -> – Validação de peça completa (hash) | C41: Vinicios | D41: =IFERROR(Planning_Poker!J32,0) -> 1 | E41: =F40 -> 46294 | F41: =E41+D41 -> 46295 | G41: 3.4.3 | H41: =D41*$C$9 -> 1200 | I41: 0 | J41: Não iniciado | K41: =E41-$C$4 -> 34 | L41: Sprint 1 (Rodada 1 -> Rodada 2)
A42: =Escopo_EAP!A47 -> 3.5.2 | B42: =TRIM(Escopo_EAP!C47) -> – Broadcast de HAVE aos peers | C42: Vinicios | D42: =IFERROR(Planning_Poker!J33,0) -> 0.5 | E42: =F41 -> 46295 | F42: =E42+D42 -> 46295.5 | G42: 3.5.1 | H42: =D42*$C$9 -> 600 | I42: 0 | J42: Não iniciado | K42: =E42-$C$4 -> 35 | L42: Sprint 1 (Rodada 1 -> Rodada 2)
...

Sheet Riscos
A1: ANÁLISE DE RISCOS
A2: Exposição = Probabilidade × Impacto (mesma escala de 5 níveis usada em aula). Priorize por exposição decrescente.
A4: ID | B4: Categoria | C4: Descrição do Risco | D4: Tipo | E4: Probabilidade | F4: Impacto | G4: Exposição | H4: Prioridade | I4: Estratégia de Resposta | J4: Plano de Contenção | K4: Plano de Contingência | L4: Responsável | M4: Status
A5: 1 | B5: Técnico | C5: Tracker é ponto único de falha (SPOF): se cair, ninguém consegue localizar peers | D5: Ameaça | E5: 0.6 | F5: 1 | G5: =E5*F5 -> 0.6 | H5: =IFERROR(RANK(G5,$G$5:$G$18,0),"") -> 1 | I5: Mitigar | J5: Manter o tracker simples e leve; logs de monitoramento básicos | K5: Reiniciar o tracker rapidamente; documentar procedimento de recuperação | M5: Não iniciado
A6: 2 | B6: Técnico | C6: Corrupção/perda de integridade dos fragmentos ao remontar o arquivo | D6: Ameaça | E6: 0.4 | F6: 0.8 | G6: =E6*F6 -> 0.32 | H6: =IFERROR(RANK(G6,$G$5:$G$18,0),"") -> 5 | I6: Mitigar | J6: Checagem de hash (SHA1) por fragmento antes de gravar em disco | K6: Rebaixar fragmento e solicitar reenvio ao peer de origem | M6: Não iniciado
A7: 3 | B7: Cronograma | C7: Funcionalidade de upload/resiliência não ficar pronta a tempo (escopo já marcado como opcional) | D7: Ameaça | E7: 0.6 | F7: 0.6 | G7: =E7*F7 -> 0.36 | H7: =IFERROR(RANK(G7,$G$5:$G$18,0),"") -> 3 | I7: Aceitar | J7: Priorizar o fluxo de download primeiro; upload como stretch goal | K7: Apresentar como 'trabalho futuro' na Rodada 3 se não concluído | M7: Não iniciado
A8: 4 | B8: Técnico | C8: Subestimar a complexidade de manter uma sessão TCP consistente durante o download | D8: Ameaça | E8: 0.4 | F8: 0.6 | G8: =E8*F8 -> 0.24 | H8: =IFERROR(RANK(G8,$G$5:$G$18,0),"") -> 6 | I8: Mitigar | J8: Prototipar cedo (spike técnico) a comunicação TCP entre 2 nós | K8: Buscar biblioteca/exemplo de referência (ex.: repositório similar no GitHub) | M8: Não iniciado
A9: 5 | B9: Equipe | C9: Indisponibilidade de um integrante-chave em período crítico do desenvolvimento | D9: Ameaça | E9: 0.4 | F9: 0.6 | G9: =E9*F9 -> 0.24 | H9: =IFERROR(RANK(G9,$G$5:$G$18,0),"") -> 6 | I9: Mitigar | J9: Distribuir conhecimento (pair programming, documentação dos módulos) | K9: Redistribuir tarefas entre os demais integrantes | M9: Não iniciado
A10: 6 | B10: Externo | C10: Perda de dados do repositório por falha do provedor (GitHub) | D10: Ameaça | E10: 0.2 | F10: 1 | G10: =E10*F10 -> 0.2 | H10: =IFERROR(RANK(G10,$G$5:$G$18,0),"") -> 8 | I10: Aceitar | J10: Cada integrante mantém clone local atualizado | K10: Restaurar a partir do clone local mais recente | M10: Não iniciado
A11: 7 | B11: Técnico | C11: Bugs de serialização binária (struct) corrompem mensagens do Peer Wire Protocol (handshake, bitfield, request/piece) | D11: Ameaça | E11: 0.6 | F11: 0.6 | G11: =E11*F11 -> 0.36 | H11: =IFERROR(RANK(G11,$G$5:$G$18,0),"") -> 3 | I11: Mitigar | J11: Testes unitários de empacotamento/desempacotamento para cada tipo de mensagem, com casos de borda | K11: Validar length prefix e IDs antes de decodificar o payload; descartar mensagem malformada | M11: Não iniciado
A12: 8 | B12: Cronograma | C12: Subestimar o esforço do Peer Wire Protocol completo (handshake + bitfield + choking + request/piece + have) — 5 pacotes de trabalho novos identificados no Anexo A | D12: Ameaça | E12: 0.6 | F12: 0.8 | G12: =E12*F12 -> 0.48 | H12: =IFERROR(RANK(G12,$G$5:$G$18,0),"") -> 2 | I12: Mitigar | J12: Fazer o Planning Poker pacote a pacote (3.1 a 3.5) em vez de estimar 'comunicação entre peers' como um bloco único | K12: Cortar HAVE (3.5) e usar bitfield-only para o v1, se o prazo apertar | M12: Não iniciado
A13: 9 | G13: =IFERROR(E13*F13,"") -> 0 | H13: =IFERROR(RANK(G13,$G$5:$G$18,0),"") -> 9 | M13: Não iniciado
A14: 10 | G14: =IFERROR(E14*F14,"") -> 0 | H14: =IFERROR(RANK(G14,$G$5:$G$18,0),"") -> 9 | M14: Não iniciado
A15: 11 | G15: =IFERROR(E15*F15,"") -> 0 | H15: =IFERROR(RANK(G15,$G$5:$G$18,0),"") -> 9 | M15: Não iniciado
A16: 12 | G16: =IFERROR(E16*F16,"") -> 0 | H16: =IFERROR(RANK(G16,$G$5:$G$18,0),"") -> 9 | M16: Não iniciado
A17: 13 | G17: =IFERROR(E17*F17,"") -> 0 | H17: =IFERROR(RANK(G17,$G$5:$G$18,0),"") -> 9 | M17: Não iniciado
A18: 14 | G18: =IFERROR(E18*F18,"") -> 0 | H18: =IFERROR(RANK(G18,$G$5:$G$18,0),"") -> 9 | M18: Não iniciado

Sheet Burndown
A1: BURNDOWN DA ITERAÇÃO
A2: Trabalho restante planejado vs. real dentro de uma iteração/sprint
A4: Trabalho do Sprint 1 (homem-dia, Fases 1-4 exceto o parser): | C4: =SUM(Planning_Poker!J5:J39) -> 27
A5: Duração do Sprint 1 (dias): | C5: 27
A7: Dia | B7: Data | C7: Trabalho Restante Planejado | D7: Trabalho Restante Real
A8: 0 | B8: =Cronograma_Orcamento!$C$5+A8 -> 46274 | C8: =$C$4*(1-A8/$C$5) -> 27 | D8: =$C$4 -> 27
A9: 1 | B9: =Cronograma_Orcamento!$C$5+A9 -> 46275 | C9: =$C$4*(1-A9/$C$5) -> 26
A10: 2 | B10: =Cronograma_Orcamento!$C$5+A10 -> 46276 | C10: =$C$4*(1-A10/$C$5) -> 25
A11: 3 | B11: =Cronograma_Orcamento!$C$5+A11 -> 46277 | C11: =$C$4*(1-A11/$C$5) -> 24
A12: 4 | B12: =Cronograma_Orcamento!$C$5+A12 -> 46278 | C12: =$C$4*(1-A12/$C$5) -> 23
A13: 5 | B13: =Cronograma_Orcamento!$C$5+A13 -> 46279 | C13: =$C$4*(1-A13/$C$5) -> 22
A14: 6 | B14: =Cronograma_Orcamento!$C$5+A14 -> 46280 | C14: =$C$4*(1-A14/$C$5) -> 21
A15: 7 | B15: =Cronograma_Orcamento!$C$5+A15 -> 46281 | C15: =$C$4*(1-A15/$C$5) -> 20
A16: 8 | B16: =Cronograma_Orcamento!$C$5+A16 -> 46282 | C16: =$C$4*(1-A16/$C$5) -> 19
A17: 9 | B17: =Cronograma_Orcamento!$C$5+A17 -> 46283 | C17: =$C$4*(1-A17/$C$5) -> 18
A18: 10 | B18: =Cronograma_Orcamento!$C$5+A18 -> 46284 | C18: =$C$4*(1-A18/$C$5) -> 17
A19: 11 | B19: =Cronograma_Orcamento!$C$5+A19 -> 46285 | C19: =$C$4*(1-A19/$C$5) -> 16
A20: 12 | B20: =Cronograma_Orcamento!$C$5+A20 -> 46286 | C20: =$C$4*(1-A20/$C$5) -> 15
... A35: 27 | B35: =Cronograma_Orcamento!$C$5+A35 -> 46301 | C35: =$C$4*(1-A35/$C$5) -> 0

Sheet EVM
A1: MONITORAMENTO E CONTROLE — ANÁLISE DE VALOR AGREGADO (EVM)
A2: PV = BAC×P%C · EV = BAC×A%C · SPI = EV/PV · CPI = EV/AC (fórmulas da Aula 6)
A4: BAC (Orçamento total): | C4: =Cronograma_Orcamento!H57 -> 52800
A6: Marco | B6: Data | C6: P%C (Planejado) | D6: A%C (Real) | E6: PV | F6: EV | G6: AC (Custo Real) | H6: CV | I6: CVP | J6: CPI | K6: SV | L6: SVP | M6: SPI
A7: Rodada 1 | B7: 46273 | C7: =IFERROR(SUMIF(Cronograma_Orcamento!$F$13:$F$56,"<="&B7,Cronograma_Orcamento!$H$13:$H$56)/$C$4,0) -> 0.022727273 | D7: =IFERROR(SUMPRODUCT(Cronograma_Orcamento!$I$13:$I$56,Cronograma_Orcamento!$H$13:$H$56)/$C$4,0) -> 0.022727273 | E7: =$C$4*C7 -> 1200 | F7: =$C$4*D7 -> 1200 | G7: =SUMPRODUCT(Cronograma_Orcamento!$I$13:$I$56,Cronograma_Orcamento!$H$13:$H$56) -> 1200 | H7: =F7-G7 -> 0 | I7: =IFERROR(H7/F7,"") -> 0 | J7: =IFERROR(F7/G7,"") -> 1 | K7: =F7-E7 -> 0 | L7: =IFERROR(K7/E7,"") -> 0 | M7: =IFERROR(F7/E7,"") -> 1
A8: Rodada 2 | B8: 46301 | C8: =IFERROR(SUMIF(Cronograma_Orcamento!$F$13:$F$56,"<="&B8,Cronograma_Orcamento!$H$13:$H$56)/$C$4,0) -> 0.63636364 | D8: 0 | E8: =$C$4*C8 -> 33600 | F8: =$C$4*D8 -> 0 | G8: 0 | H8: =F8-G8 -> 0 | I8: =IFERROR(H8/F8,"") | J8: =IFERROR(F8/G8,"") | K8: =F8-E8 -> -33600 | L8: =IFERROR(K8/E8,"") -> -1 | M8: =IFERROR(F8/E8,"") -> 0
A9: Rodada 3 | B9: 46336 | C9: =IFERROR(SUMIF(Cronograma_Orcamento!$F$13:$F$56,"<="&B9,Cronograma_Orcamento!$H$13:$H$56)/$C$4,0) -> 1 | D9: 0 | E9: =$C$4*C9 -> 52800 | F9: =$C$4*D9 -> 0 | G9: 0 | H9: =F9-G9 -> 0 | I9: =IFERROR(H9/F9,"") | J9: =IFERROR(F9/G9,"") | K9: =F9-E9 -> -52800 | L9: =IFERROR(K9/E9,"") -> -1 | M9: =IFERROR(F9/E9,"") -> 0

Sheet Listas
A1: Status | C1: Probabilidade | E1: Impacto | G1: Estrategia | I1: Categoria_Risco | K1: Tipo_Risco | M1: Unidade_Estimativa
A2: Não iniciado | C2: 0.2 | E2: 0.2 | G2: Evitar | I2: Técnico | K2: Ameaça | M2: Homem-dia
A3: Em andamento | C3: 0.4 | E3: 0.4 | G3: Mitigar | I3: Cronograma | K3: Oportunidade | M3: Pontos
A4: Concluído | C4: 0.6 | E4: 0.6 | G4: Transferir | I4: Equipe
A5: Bloqueado | C5: 0.8 | E5: 0.8 | G5: Aceitar | I5: Externo
C6: 1 | E6: 1 | G6: Explorar | I6: Escopo
G7: Potencializar
G8: Compartilhar
